+p_xml: 'version="1.0" encoding="UTF-8" standalone="yes" '
+directive: DOCTYPE bugzilla SYSTEM "http://bugzilla.fieldtriptoolbox.org/page.cgi?id=bugzilla.dtd"
bugzilla:
  +@version: 4.4.1
  +@urlbase: http://bugzilla.fieldtriptoolbox.org/
  +@maintainer: r.oostenveld@donders.ru.nl
  bug:
    bug_id: "2832"
    creation_ts: 2015-02-10 15:20:00 +0100
    short_desc: cfg.debug=saveonerror fails after rollback_provenance
    delta_ts: 2015-02-11 09:46:54 +0100
    reporter_accessible: "1"
    cclist_accessible: "1"
    classification_id: "1"
    classification: Unclassified
    product: FieldTrip
    component: core
    version: unspecified
    rep_platform: PC
    op_sys: Mac OS
    bug_status: NEW
    resolution:
    see_also:
      - http://bugzilla.fcdonders.nl/show_bug.cgi?id=2655
      - http://bugzilla.fcdonders.nl/show_bug.cgi?id=1950
    bug_file_loc:
    status_whiteboard:
    keywords:
    priority: P5
    bug_severity: normal
    target_milestone: '---'
    everconfirmed: "1"
    reporter:
      +content: r.oostenveld
      +@name: Robert Oostenveld
    assigned_to: fieldtriptoolbox
    comment_sort_order: oldest_to_newest
    long_desc:
      +@isprivate: "0"
      commentid: "15193"
      comment_count: "0"
      who:
        +content: r.oostenveld
        +@name: Robert Oostenveld
      bug_when: 2015-02-10 15:20:34 +0100
      thetext: |-
        Eelke reported in bug 2830 that cfg.debug='saveonerror' did not work for him.

        I was able to reproduce and localise it. In ft_sourcestatistics around line 119 there is

        % ensure that the data in all inputs has the same channels, time-axis, etc.
        tmpcfg = keepfields(cfg, {'frequency', 'avgoverfreq', 'latency', 'avgovertime', 'parameter'});
        [varargin{:}] = ft_selectdata(tmpcfg, varargin{:});
        % restore the provenance information
        [cfg, varargin{:}] = rollback_provenance(cfg, varargin{:});

        If I add
          error('test')
        just before this section, the saveonerror handling works.

        If I add
          error('test')
        just after this section, the saveonerror handling does not work.

        This problem might be related to bug 2655.
