+p_xml: 'version="1.0" encoding="UTF-8" standalone="yes" '
+directive: DOCTYPE bugzilla SYSTEM "http://bugzilla.fieldtriptoolbox.org/page.cgi?id=bugzilla.dtd"
bugzilla:
  +@version: 4.4.1
  +@urlbase: http://bugzilla.fieldtriptoolbox.org/
  +@maintainer: r.oostenveld@donders.ru.nl
  bug:
    bug_id: "3461"
    creation_ts: 2018-10-22 15:27:00 +0200
    short_desc: problem with ft_sourcestatistics when using output of ft_sourcegrandaverage
    delta_ts: 2019-08-10 12:37:23 +0200
    reporter_accessible: "1"
    cclist_accessible: "1"
    classification_id: "1"
    classification: Unclassified
    product: FieldTrip
    component: core
    version: unspecified
    rep_platform: PC
    op_sys: Windows
    bug_status: CLOSED
    resolution: FIXED
    bug_file_loc:
    status_whiteboard:
    keywords:
    priority: P5
    bug_severity: minor
    target_milestone: '---'
    everconfirmed: "1"
    reporter:
      +content: m.manahova
      +@name: Mariya Manahova
    assigned_to: fieldtriptoolbox
    cc: r.oostenveld
    comment_sort_order: oldest_to_newest
    long_desc:
      - +@isprivate: "0"
        commentid: "19508"
        comment_count: "0"
        attachid: "879"
        who:
          +content: m.manahova
          +@name: Mariya Manahova
        bug_when: 2018-10-22 15:27:33 +0200
        thetext: |-
          Created attachment 879
          Script that produces the error

          When I try to run ft_sourcestatistics on output of ft_sourcegrandaverage (cfg.keepindividual = 'yes'), I get the following error:

          Error using ft_statistics_montecarlo (line 244)
          could not determine the parametric critical value for clustering

          Error in ft_sourcestatistics (line 211)
            [stat, cfg] = statmethod(cfg, dat, design);

          Instead, when I run ft_sourcestatistics on the source structures in a cell array (not grand averaged), I don't encounter a problem.
      - +@isprivate: "0"
        commentid: "19511"
        comment_count: "1"
        who:
          +content: r.oostenveld
          +@name: Robert Oostenveld
        bug_when: 2018-10-23 11:52:25 +0200
        thetext: '*** Bug 3462 has been marked as a duplicate of this bug. ***'
      - +@isprivate: "0"
        commentid: "19512"
        comment_count: "2"
        who:
          +content: r.oostenveld
          +@name: Robert Oostenveld
        bug_when: 2018-10-23 13:35:30 +0200
        thetext: I solved this with https://github.com/fieldtrip/fieldtrip/pull/857
      - +@isprivate: "0"
        commentid: "19513"
        comment_count: "3"
        who:
          +content: r.oostenveld
          +@name: Robert Oostenveld
        bug_when: 2018-10-23 13:36:38 +0200
        thetext: the problem had to do with the detection of the data dimensions (i.e. dimord). I fixed ft_sourvcegrandaverage so that it better uses the modern dimord handling.
      - +@isprivate: "0"
        commentid: "20381"
        comment_count: "4"
        who:
          +content: r.oostenveld
          +@name: Robert Oostenveld
        bug_when: 2019-08-10 12:37:23 +0200
        thetext: "This closes a whole series of bugs that have been resolved (either FIXED/WONTFIX/INVALID) for quite some time. \n\nIf you disagree, please file a new issue on https://github.com/fieldtrip/fieldtrip/issues."
    attachment:
      +@isobsolete: "0"
      +@ispatch: "0"
      +@isprivate: "0"
      attachid: "879"
      date: 2018-10-22 15:27:00 +0200
      delta_ts: 2018-10-22 15:27:33 +0200
      desc: Script that produces the error
      filename: analysisSourceTmapsBug.m
      type: text/plain
      size: "1153"
      attacher:
        +content: m.manahova
        +@name: Mariya Manahova
      data: REMOVED
